<?xml version="1.0" encoding="utf-8"?>
<robot name="aliengo">
    <material name="black">
        <color rgba="0.0 0.0 0.0 1.0"/>
    </material>
    <material name="blue">
        <color rgba="0.0 0.0 0.8 1.0"/>
    </material>
    <material name="green">
        <color rgba="0.0 0.8 0.0 1.0"/>
    </material>
    <material name="grey">
        <color rgba="0.25 0.25 0.25 1."/>
    </material>
    <material name="light_grey">
        <color rgba="0.35 0.35 0.35 1.0"/>
    </material>
    <material name="red">
        <color rgba="0.45 0.13 0.13 1.0"/>
    </material>
    <material name="silver">
        <color rgba="0.913725490196 0.913725490196 0.847058823529 1.0"/>
    </material>
    <material name="orange">
        <color rgba="1.0 0.423529411765 0.0392156862745 1.0"/>
    </material>
    <material name="brown">
        <color rgba="0.870588235294 0.811764705882 0.764705882353 1.0"/>
    </material>
    <material name="white_gray">
        <color rgba="0.823529411765 0.823529411765 0.823529411765 1.0"/>
    </material>
    <material name="gold">
        <color rgba="0.811764705882 0.678431372549 0.301960784314 1.0"/>
    </material>
    <material name="white_blue">
        <color rgba="0.462745098039 0.8 0.992156862745 1.0"/>
    </material>
    <material name="white_black">
        <color rgba="0.494117647059 0.494117647059 0.494117647059 1.0"/>
    </material>
    <material name="white">
        <color rgba="1.0 1.0 1.0 1.0"/>
    </material>

    <link name="base">
        <inertial>
            <origin rpy="0 0 0" xyz="0 0 0"/>
            <mass value="1.001"/>
            <inertia ixx="0" ixy="0" ixz="0" iyy="0" iyz="0" izz="0"/>
        </inertial>
        <!--        <visual>-->
        <!--            <origin rpy="0 0 0" xyz="0 0 0"/>-->
        <!--            <geometry>-->
        <!--                <box size="0.001 0.001 0.001"/>-->
        <!--            </geometry>-->
        <!--        </visual>-->
    </link>
    <joint name="trunk_fixed" type="fixed">
        <origin rpy="0 0 0" xyz="0 0 0"/>
        <parent link="base"/>
        <child link="trunk"/>
    </joint>
    <link name="trunk">
        <inertial>
            <origin rpy="0 0 0" xyz="0.008465 0.004045 -0.000763"/>
            <mass value="9.041"/>
            <inertia ixx="0.033260231" ixy="-0.000451628" ixz="0.000487603" iyy="0.16117211" iyz="4.8356e-05" izz="0.17460442"/>
        </inertial>
        <visual>
            <origin rpy="0 0 0" xyz="0 0 0"/>
            <geometry>
                <mesh filename="../meshes/trunk.stl" scale="1 1 1"/>
            </geometry>
            <material name="grey"/>
        </visual>
        <collision>
            <origin rpy="0 0 0" xyz="0 0 0"/>
            <geometry>
                <box size="0.647 0.15 0.112"/>
            </geometry>
        </collision>
    </link>
    <!--    <joint name="payload_fixed" type="fixed">-->
    <!--        <origin rpy="0 0 0" xyz="0 0 0"/>-->
    <!--        <parent link="base"/>-->
    <!--        <child link="payload"/>-->
    <!--    </joint>-->
    <!--    <link name="payload">-->
    <!--        <inertial>-->
    <!--            <origin xyz="0 0 0" rpy="0 0 0"/>-->
    <!--            <mass value="0.001"/>-->
    <!--            <inertia ixx="0" ixy="0" ixz="0" iyy="0" iyz="0" izz="0"/>-->
    <!--        </inertial>-->
    <!--        <visual>-->
    <!--            <origin xyz="0 0 0.06" rpy="0 0 0"/>-->
    <!--            <geometry>-->
    <!--                <cylinder length="0.001" radius="0.05"/>-->
    <!--            </geometry>-->
    <!--            <material name="red"/>-->
    <!--        </visual>-->
    <!--        <collision>-->
    <!--            <origin xyz="0 0 0.06" rpy="0 0 0"/>-->
    <!--            <geometry>-->
    <!--                <cylinder length="0.001" radius="0.05"/>-->
    <!--            </geometry>-->
    <!--        </collision>-->
    <!--    </link>-->
    <!--    <joint name="imu_fixed" type="fixed">-->
    <!--        <parent link="base"/>-->
    <!--        <child link="imu_link"/>-->
    <!--        <origin rpy="0 0 0" xyz="0 0 0"/>-->
    <!--    </joint>-->
    <!--    <link name="imu_link">-->
    <!--        <inertial>-->
    <!--            <mass value="0.001"/>-->
    <!--            <origin rpy="0 0 0" xyz="0 0 0"/>-->
    <!--            <inertia ixx="0.0001" ixy="0" ixz="0" iyy="0.000001" iyz="0" izz="0.0001"/>-->
    <!--        </inertial>-->
    <!--        <visual>-->
    <!--            <origin rpy="0 0 0" xyz="0 0 0"/>-->
    <!--            <geometry>-->
    <!--                <box size="0.001 0.001 0.001"/>-->
    <!--            </geometry>-->
    <!--            <material name="red"/>-->
    <!--        </visual>-->
    <!--        <collision>-->
    <!--            <origin rpy="0 0 0" xyz="0 0 0"/>-->
    <!--            <geometry>-->
    <!--                <box size=".001 .001 .001"/>-->
    <!--            </geometry>-->
    <!--        </collision>-->
    <!--    </link>-->

    <!-- RF leg -->
    <joint name="RF_hip_joint" type="revolute">
        <origin rpy="0 0 0" xyz="0.2399 -0.051 0"/>
        <parent link="trunk"/>
        <child link="RF_hip"/>
        <axis xyz="1 0 0"/>
        <dynamics damping="0" friction="0"/>
        <limit effort="44" velocity="20" lower="-1.22" upper="1.22"/>
    </joint>
    <link name="RF_hip">
        <inertial>
            <origin rpy="0 0 0" xyz="-0.022191 -0.015144 -1.5e-05"/>
            <mass value="1.993"/>
            <inertia ixx="0.002903894" ixy="7.185e-05" ixz="-1.262e-06" iyy="0.004907517" iyz="1.75e-06" izz="0.005586944"/>
        </inertial>
        <visual>
            <origin rpy="3.14159265359 0 0" xyz="0 0 0"/>
            <geometry>
                <mesh filename="../meshes/hip.stl" scale="1 1 1"/>
            </geometry>
            <material name="light_grey"/>
        </visual>
        <collision>
            <origin rpy="1.57079632679 0 0" xyz="0 -0.083 0"/>
            <geometry>
                <cylinder length="0.0418" radius="0.046"/>
            </geometry>
        </collision>
    </link>
    <joint name="RF_thigh_joint" type="revolute">
        <origin rpy="0 0 0" xyz="0 -0.083 0"/>
        <parent link="RF_hip"/>
        <child link="RF_thigh"/>
        <axis xyz="0 1 0"/>
        <dynamics damping="0" friction="0"/>
        <limit effort="44" velocity="20" lower="-3.14" upper="3.14"/>
    </joint>
    <link name="RF_thigh">
        <inertial>
            <origin rpy="0 0 0" xyz="-0.005607 0.003877 -0.048199"/>
            <mass value="0.639"/>
            <inertia ixx="0.005666803" ixy="-3.597e-06" ixz="0.000491446" iyy="0.005847229" iyz="-1.0086e-05" izz="0.000369811"/>
        </inertial>
        <visual>
            <origin rpy="0 0 0" xyz="0 0 0"/>
            <geometry>
                <mesh filename="../meshes/thigh_mirror.stl" scale="1 1 1"/>
            </geometry>
            <material name="light_grey"/>
        </visual>
        <collision>
            <origin rpy="0 1.57079632679 0" xyz="0 0 -0.125"/>
            <geometry>
                <box size="0.25 0.0374 0.043"/>
            </geometry>
        </collision>
    </link>
    <joint name="RF_calf_joint" type="revolute">
        <origin rpy="0 0 0" xyz="0 0 -0.25"/>
        <parent link="RF_thigh"/>
        <child link="RF_calf"/>
        <axis xyz="0 1 0"/>
        <dynamics damping="0" friction="0"/>
        <limit effort="55" velocity="16" lower="-2.75" upper="-0.64"/>
    </joint>
    <link name="RF_calf">
        <inertial>
            <origin rpy="0 0 0" xyz="0.002781 6.3e-05 -0.142518"/>
            <mass value="0.207"/>
            <inertia ixx="0.006341369" ixy="-3e-09" ixz="-8.7951e-05" iyy="0.006355157" iyz="-1.336e-06" izz="3.9188e-05"/>
        </inertial>
        <visual>
            <origin rpy="0 0 0" xyz="0 0 0"/>
            <geometry>
                <mesh filename="../meshes/calf.stl" scale="1 1 1"/>
            </geometry>
            <material name="light_grey"/>
        </visual>
        <collision>
            <origin rpy="0 1.57079632679 0" xyz="0 0 -0.125"/>
            <geometry>
                <box size="0.25 0.0208 0.016"/>
            </geometry>
        </collision>
    </link>
    <joint name="RF_foot_fixed" type="fixed">
        <origin rpy="0 0 0" xyz="0 0 -0.25"/>
        <parent link="RF_calf"/>
        <child link="RF_foot"/>
    </joint>
    <link name="RF_foot">
        <inertial>
            <mass value="0.06"/>
            <inertia ixx="1.6854e-05" ixy="0" ixz="0" iyy="1.6854e-05" iyz="0" izz="1.6854e-05"/>
        </inertial>
        <visual>
            <origin rpy="0 0 0" xyz="0 0 0"/>
            <geometry>
                <sphere radius="0.0165"/>
            </geometry>
            <material name="green"/>
        </visual>
        <collision>
            <origin rpy="0 0 0" xyz="0 0 0"/>
            <geometry>
                <sphere radius="0.0265"/>
            </geometry>
        </collision>
    </link>

    <!-- LF leg -->
    <joint name="LF_hip_joint" type="revolute">
        <origin rpy="0 0 0" xyz="0.2399 0.051 0"/>
        <parent link="trunk"/>
        <child link="LF_hip"/>
        <axis xyz="1 0 0"/>
        <dynamics damping="0" friction="0"/>
        <limit effort="44" velocity="20" lower="-1.22" upper="1.22"/>
    </joint>
    <link name="LF_hip">
        <inertial>
            <origin rpy="0 0 0" xyz="-0.022191 0.015144 -1.5e-05"/>
            <mass value="1.993"/>
            <inertia ixx="0.002903894" ixy="-7.185e-05" ixz="-1.262e-06" iyy="0.004907517" iyz="-1.75e-06" izz="0.005586944"/>
        </inertial>
        <visual>
            <origin rpy="0 0 0" xyz="0 0 0"/>
            <geometry>
                <mesh filename="../meshes/hip.stl" scale="1 1 1"/>
            </geometry>
            <material name="light_grey"/>
        </visual>
        <collision>
            <origin rpy="1.57079632679 0 0" xyz="0 0.083 0"/>
            <geometry>
                <cylinder length="0.0418" radius="0.046"/>
            </geometry>
        </collision>
    </link>
    <joint name="LF_thigh_joint" type="revolute">
        <origin rpy="0 0 0" xyz="0 0.083 0"/>
        <parent link="LF_hip"/>
        <child link="LF_thigh"/>
        <axis xyz="0 1 0"/>
        <dynamics damping="0" friction="0"/>
        <limit effort="44" velocity="20" lower="-3.14" upper="3.14"/>
    </joint>
    <link name="LF_thigh">
        <inertial>
            <origin rpy="0 0 0" xyz="-0.005607 -0.003877 -0.048199"/>
            <mass value="0.639"/>
            <inertia ixx="0.005666803" ixy="3.597e-06" ixz="0.000491446" iyy="0.005847229" iyz="1.0086e-05" izz="0.000369811"/>
        </inertial>
        <visual>
            <origin rpy="0 0 0" xyz="0 0 0"/>
            <geometry>
                <mesh filename="../meshes/thigh.stl" scale="1 1 1"/>
            </geometry>
            <material name="light_grey"/>
        </visual>
        <collision>
            <origin rpy="0 1.57079632679 0" xyz="0 0 -0.125"/>
            <geometry>
                <box size="0.25 0.0374 0.043"/>
            </geometry>
        </collision>
    </link>
    <joint name="LF_calf_joint" type="revolute">
        <origin rpy="0 0 0" xyz="0 0 -0.25"/>
        <parent link="LF_thigh"/>
        <child link="LF_calf"/>
        <axis xyz="0 1 0"/>
        <dynamics damping="0" friction="0"/>
        <limit effort="55" velocity="16" lower="-2.75" upper="-0.64"/>
    </joint>
    <link name="LF_calf">
        <inertial>
            <origin rpy="0 0 0" xyz="0.002781 6.3e-05 -0.142518"/>
            <mass value="0.207"/>
            <inertia ixx="0.006341369" ixy="-3e-09" ixz="-8.7951e-05" iyy="0.006355157" iyz="-1.336e-06" izz="3.9188e-05"/>
        </inertial>
        <visual>
            <origin rpy="0 0 0" xyz="0 0 0"/>
            <geometry>
                <mesh filename="../meshes/calf.stl" scale="1 1 1"/>
            </geometry>
            <material name="light_grey"/>
        </visual>
        <collision>
            <origin rpy="0 1.57079632679 0" xyz="0 0 -0.125"/>
            <geometry>
                <box size="0.25 0.0208 0.016"/>
            </geometry>
        </collision>
    </link>
    <joint name="LF_foot_fixed" type="fixed">
        <origin rpy="0 0 0" xyz="0 0 -0.25"/>
        <parent link="LF_calf"/>
        <child link="LF_foot"/>
    </joint>
    <link name="LF_foot">
        <inertial>
            <mass value="0.06"/>
            <inertia ixx="1.6854e-05" ixy="0" ixz="0" iyy="1.6854e-05" iyz="0" izz="1.6854e-05"/>
        </inertial>
        <visual>
            <origin rpy="0 0 0" xyz="0 0 0"/>
            <geometry>
                <sphere radius="0.0165"/>
            </geometry>
            <material name="green"/>
        </visual>
        <collision>
            <origin rpy="0 0 0" xyz="0 0 0"/>
            <geometry>
                <sphere radius="0.0265"/>
            </geometry>
        </collision>
    </link>

    <!-- RR leg -->
    <joint name="RR_hip_joint" type="revolute">
        <origin rpy="0 0 0" xyz="-0.2399 -0.051 0"/>
        <parent link="trunk"/>
        <child link="RR_hip"/>
        <axis xyz="1 0 0"/>
        <dynamics damping="0" friction="0"/>
        <limit effort="44" velocity="20" lower="-1.22" upper="1.22"/>
    </joint>
    <link name="RR_hip">
        <inertial>
            <origin rpy="0 0 0" xyz="0.022191 -0.015144 -1.5e-05"/>
            <mass value="1.993"/>
            <inertia ixx="0.002903894" ixy="-7.185e-05" ixz="1.262e-06" iyy="0.004907517" iyz="1.75e-06" izz="0.005586944"/>
        </inertial>
        <visual>
            <origin rpy="3.14159265359 3.14159265359 0" xyz="0 0 0"/>
            <geometry>
                <mesh filename="../meshes/hip.stl" scale="1 1 1"/>
            </geometry>
            <material name="light_grey"/>
        </visual>
        <collision>
            <origin rpy="1.57079632679 0 0" xyz="0 -0.083 0"/>
            <geometry>
                <cylinder length="0.0418" radius="0.046"/>
            </geometry>
        </collision>
    </link>
    <joint name="RR_thigh_joint" type="revolute">
        <origin rpy="0 0 0" xyz="0 -0.083 0"/>
        <parent link="RR_hip"/>
        <child link="RR_thigh"/>
        <axis xyz="0 1 0"/>
        <dynamics damping="0" friction="0"/>
        <limit effort="44" velocity="20" lower="-3.14" upper="3.14"/>
    </joint>
    <link name="RR_thigh">
        <inertial>
            <origin rpy="0 0 0" xyz="-0.005607 0.003877 -0.048199"/>
            <mass value="0.639"/>
            <inertia ixx="0.005666803" ixy="-3.597e-06" ixz="0.000491446" iyy="0.005847229" iyz="-1.0086e-05" izz="0.000369811"/>
        </inertial>
        <visual>
            <origin rpy="0 0 0" xyz="0 0 0"/>
            <geometry>
                <mesh filename="../meshes/thigh_mirror.stl" scale="1 1 1"/>
            </geometry>
            <material name="light_grey"/>
        </visual>
        <collision>
            <origin rpy="0 1.57079632679 0" xyz="0 0 -0.125"/>
            <geometry>
                <box size="0.25 0.0374 0.043"/>
            </geometry>
        </collision>
    </link>
    <joint name="RR_calf_joint" type="revolute">
        <origin rpy="0 0 0" xyz="0 0 -0.25"/>
        <parent link="RR_thigh"/>
        <child link="RR_calf"/>
        <axis xyz="0 1 0"/>
        <dynamics damping="0" friction="0"/>
        <limit effort="55" velocity="16" lower="-2.75" upper="-0.64"/>
    </joint>
    <link name="RR_calf">
        <inertial>
            <origin rpy="0 0 0" xyz="0.002781 6.3e-05 -0.142518"/>
            <mass value="0.207"/>
            <inertia ixx="0.006341369" ixy="-3e-09" ixz="-8.7951e-05" iyy="0.006355157" iyz="-1.336e-06" izz="3.9188e-05"/>
        </inertial>
        <visual>
            <origin rpy="0 0 0" xyz="0 0 0"/>
            <geometry>
                <mesh filename="../meshes/calf.stl" scale="1 1 1"/>
            </geometry>
            <material name="light_grey"/>
        </visual>
        <collision>
            <origin rpy="0 1.57079632679 0" xyz="0 0 -0.125"/>
            <geometry>
                <box size="0.25 0.0208 0.016"/>
            </geometry>
        </collision>
    </link>
    <joint name="RR_foot_fixed" type="fixed">
        <origin rpy="0 0 0" xyz="0 0 -0.25"/>
        <parent link="RR_calf"/>
        <child link="RR_foot"/>
    </joint>
    <link name="RR_foot">
        <inertial>
            <mass value="0.06"/>
            <inertia ixx="1.6854e-05" ixy="0" ixz="0" iyy="1.6854e-05" iyz="0" izz="1.6854e-05"/>
        </inertial>
        <visual>
            <origin rpy="0 0 0" xyz="0 0 0"/>
            <geometry>
                <sphere radius="0.0165"/>
            </geometry>
            <material name="green"/>
        </visual>
        <collision>
            <origin rpy="0 0 0" xyz="0 0 0"/>
            <geometry>
                <sphere radius="0.0265"/>
            </geometry>
        </collision>
    </link>

    <!-- LR leg -->
    <joint name="LR_hip_joint" type="revolute">
        <origin rpy="0 0 0" xyz="-0.2399 0.051 0"/>
        <parent link="trunk"/>
        <child link="LR_hip"/>
        <axis xyz="1 0 0"/>
        <dynamics damping="0" friction="0"/>
        <limit effort="44" velocity="20" lower="-1.22" upper="1.22"/>
    </joint>
    <link name="LR_hip">
        <inertial>
            <origin rpy="0 0 0" xyz="0.022191 0.015144 -1.5e-05"/>
            <mass value="1.993"/>
            <inertia ixx="0.002903894" ixy="7.185e-05" ixz="1.262e-06" iyy="0.004907517" iyz="-1.75e-06" izz="0.005586944"/>
        </inertial>
        <visual>
            <origin rpy="0 3.14159265359 0" xyz="0 0 0"/>
            <geometry>
                <mesh filename="../meshes/hip.stl" scale="1 1 1"/>
            </geometry>
            <material name="light_grey"/>
        </visual>
        <collision>
            <origin rpy="1.57079632679 0 0" xyz="0 0.083 0"/>
            <geometry>
                <cylinder length="0.0418" radius="0.046"/>
            </geometry>
        </collision>
    </link>
    <joint name="LR_thigh_joint" type="revolute">
        <origin rpy="0 0 0" xyz="0 0.083 0"/>
        <parent link="LR_hip"/>
        <child link="LR_thigh"/>
        <axis xyz="0 1 0"/>
        <dynamics damping="0" friction="0"/>
        <limit effort="44" velocity="20" lower="-3.14" upper="3.14"/>
    </joint>
    <link name="LR_thigh">
        <inertial>
            <origin rpy="0 0 0" xyz="-0.005607 -0.003877 -0.048199"/>
            <mass value="0.639"/>
            <inertia ixx="0.005666803" ixy="3.597e-06" ixz="0.000491446" iyy="0.005847229" iyz="1.0086e-05" izz="0.000369811"/>
        </inertial>
        <visual>
            <origin rpy="0 0 0" xyz="0 0 0"/>
            <geometry>
                <mesh filename="../meshes/thigh.stl" scale="1 1 1"/>
            </geometry>
            <material name="light_grey"/>
        </visual>
        <collision>
            <origin rpy="0 1.57079632679 0" xyz="0 0 -0.125"/>
            <geometry>
                <box size="0.25 0.0374 0.043"/>
            </geometry>
        </collision>
    </link>
    <joint name="LR_calf_joint" type="revolute">
        <origin rpy="0 0 0" xyz="0 0 -0.25"/>
        <parent link="LR_thigh"/>
        <child link="LR_calf"/>
        <axis xyz="0 1 0"/>
        <dynamics damping="0" friction="0"/>
        <limit effort="55" velocity="16" lower="-2.75" upper="-0.64"/>
    </joint>
    <link name="LR_calf">
        <inertial>
            <origin rpy="0 0 0" xyz="0.002781 6.3e-05 -0.142518"/>
            <mass value="0.207"/>
            <inertia ixx="0.006341369" ixy="-3e-09" ixz="-8.7951e-05" iyy="0.006355157" iyz="-1.336e-06" izz="3.9188e-05"/>
        </inertial>
        <visual>
            <origin rpy="0 0 0" xyz="0 0 0"/>
            <geometry>
                <mesh filename="../meshes/calf.stl" scale="1 1 1"/>
            </geometry>
            <material name="light_grey"/>
        </visual>
        <collision>
            <origin rpy="0 1.57079632679 0" xyz="0 0 -0.125"/>
            <geometry>
                <box size="0.25 0.0208 0.016"/>
            </geometry>
        </collision>
    </link>
    <joint name="LR_foot_fixed" type="fixed">
        <origin rpy="0 0 0" xyz="0 0 -0.25"/>
        <parent link="LR_calf"/>
        <child link="LR_foot"/>
    </joint>
    <link name="LR_foot">
        <inertial>
            <mass value="0.06"/>
            <inertia ixx="1.6854e-05" ixy="0" ixz="0" iyy="1.6854e-05" iyz="0" izz="1.6854e-05"/>
        </inertial>
        <visual>
            <origin rpy="0 0 0" xyz="0 0 0"/>
            <geometry>
                <sphere radius="0.0165"/>
            </geometry>
            <material name="green"/>
        </visual>
        <collision>
            <origin rpy="0 0 0" xyz="0 0 0"/>
            <geometry>
                <sphere radius="0.0265"/>
            </geometry>
        </collision>
    </link>
</robot>

